Workbook
Name Slicer_Status: #N/A

Sheet Equipment_Master
A1: Equipment_ID | B1: Equipment_Name | C1: Equipment_Type | D1: Criticality | E1: Location | F1: Installed_Date | G1: Status
A2: EQ-100 | B2: Diesel Generator A-100 | C2: Diesel Generator | D2: Critical | E2: Onshore Facility | F2: 2021-03-25 | G2: Operational
A3: EQ-101 | B3: Gas Turbine A-101 | C3: Gas Turbine | D3: Critical | E3: Platform A | F3: 2017-05-10 | G3: Operational
A4: EQ-102 | B4: Centrifugal Pump A-102 | C4: Centrifugal Pump | D4: Critical | E4: Platform B | F4: 2018-04-24 | G4: Operational
A5: EQ-103 | B5: Storage Tank A-103 | C5: Storage Tank | D5: Critical | E5: Processing Unit | F5: 2021-07-04 | G5: Operational
A6: EQ-104 | B6: Control Valve A-104 | C6: Control Valve | D6: Low | E6: Platform A | F6: 2022-03-10 | G6: Operational
A7: EQ-105 | B7: Electric Motor A-105 | C7: Electric Motor | D7: High | E7: Platform B | F7: 2020-03-15 | G7: Operational
A8: EQ-106 | B8: Turbine A-106 | C8: Turbine | D8: Critical | E8: Onshore Facility | F8: 2017-03-17 | G8: Operational
A9: EQ-107 | B9: Centrifugal Pump A-107 | C9: Centrifugal Pump | D9: Medium | E9: Platform A | F9: 2019-09-25 | G9: Operational
A10: EQ-108 | B10: Control Valve A-108 | C10: Control Valve | D10: Low | E10: Onshore Facility | F10: 2017-07-03 | G10: Operational
A11: EQ-109 | B11: Gas Compressor A-109 | C11: Gas Compressor | D11: Critical | E11: Platform B | F11: 2020-09-24 | G11: Standby
A12: EQ-110 | B12: Reactor B-110 | C12: Reactor | D12: High | E12: Platform A | F12: 2019-09-19 | G12: Operational
... A31: EQ-129 | B31: Centrifugal Pump C-129 | C31: Centrifugal Pump | D31: Critical | E31: Onshore Facility | F31: 2020-07-12 | G31: Operational

Sheet Work_Orders
A1: WO_Number | B1: Equipment_ID | C1: Equipment_Name | D1: Maintenance_Type | E1: Priority | F1: Status | G1: Created_Date | H1: Scheduled_Start | I1: Actual_Start | J1: Completion_Date | K1: Downtime_Hours | L1: Cost_NGN | M1: Failure_Type | N1: Technician | O1: Description | P1: Year_Month | Q1: Status_Order | R1: Maintenance_Type_Order | S1: Year_Month2
A2: WO-1000 | B2: EQ-100 | C2: Diesel Generator A-100 | D2: Inspection | E2: Critical | F2: Completed | G2: 2025-01-31 | H2: 2025-01-31 21:44 | I2: 2025-01-31 21:44 | J2: 2025-01-31 23:00 | K2: 3.3 | L2: 81266.75 | M2: No Failure | N2: Chidi Eze | O2: Inspection maintenance on Diesel Generator A-100 | P2: =TEXT(G2,"yyyy-mm") -> 2025-01 | Q2: =IF(tblWO[[#This Row],[Status]]="Completed",1, IF(tblWO[[#This Row],[Status]]="In Progress",2, IF(tblWO[[#This Row],[Status]]="Planned",3, IF(tblWO[[#This Row],[Status]]="Cancelled",4,99)))) -> 1 | R2: =IF(D2="Preventive",1, IF(D2="Inspection",2, IF(D2="Corrective",3, IF(D2="Breakdown",4, IF(D2="Overhaul",5,99))))) -> 2 | S2: =TEXT(G2,"yyyy-mm") -> 2025-01
A3: WO-1001 | B3: EQ-100 | C3: Diesel Generator A-100 | D3: Corrective | E3: Medium | F3: In Progress | G3: 2025-03-16 | H3: 2025-03-16 21:44 | K3: 0 | L3: 0 | N3: Fatima Bello | O3: Corrective maintenance on Diesel Generator A-100 | P3: =TEXT(G3,"yyyy-mm") -> 2025-03 | Q3: =IF(tblWO[[#This Row],[Status]]="Completed",1, IF(tblWO[[#This Row],[Status]]="In Progress",2, IF(tblWO[[#This Row],[Status]]="Planned",3, IF(tblWO[[#This Row],[Status]]="Cancelled",4,99)))) -> 2 | R3: =IF(D3="Preventive",1, IF(D3="Inspection",2, IF(D3="Corrective",3, IF(D3="Breakdown",4, IF(D3="Overhaul",5,99))))) -> 3 | S3: =TEXT(G3,"yyyy-mm") -> 2025-03
A4: WO-1002 | B4: EQ-100 | C4: Diesel Generator A-100 | D4: Inspection | E4: Low | F4: Completed | G4: 2025-12-10 | H4: 2025-12-10 21:44 | I4: 2025-12-10 21:44 | J4: 2025-12-10 23:20 | K4: 2.9 | L4: 55048.01 | M4: No Failure | N4: Zainab Yusuf | O4: Inspection maintenance on Diesel Generator A-100 | P4: =TEXT(G4,"yyyy-mm") -> 2025-12 | Q4: =IF(tblWO[[#This Row],[Status]]="Completed",1, IF(tblWO[[#This Row],[Status]]="In Progress",2, IF(tblWO[[#This Row],[Status]]="Planned",3, IF(tblWO[[#This Row],[Status]]="Cancelled",4,99)))) -> 1 | R4: =IF(D4="Preventive",1, IF(D4="Inspection",2, IF(D4="Corrective",3, IF(D4="Breakdown",4, IF(D4="Overhaul",5,99))))) -> 2 | S4: =TEXT(G4,"yyyy-mm") -> 2025-12
A5: WO-1003 | B5: EQ-100 | C5: Diesel Generator A-100 | D5: Preventive | E5: Medium | F5: Completed | G5: 2025-04-16 | H5: 2025-04-16 21:44 | I5: 2025-04-16 21:44 | J5: 2025-04-17 00:23 | K5: 7.9 | L5: 51797.71 | M5: No Failure | N5: John Okafor | O5: Preventive maintenance on Diesel Generator A-100 | P5: =TEXT(G5,"yyyy-mm") -> 2025-04 | Q5: =IF(tblWO[[#This Row],[Status]]="Completed",1, IF(tblWO[[#This Row],[Status]]="In Progress",2, IF(tblWO[[#This Row],[Status]]="Planned",3, IF(tblWO[[#This Row],[Status]]="Cancelled",4,99)))) -> 1 | R5: =IF(D5="Preventive",1, IF(D5="Inspection",2, IF(D5="Corrective",3, IF(D5="Breakdown",4, IF(D5="Overhaul",5,99))))) -> 1 | S5: =TEXT(G5,"yyyy-mm") -> 2025-04
A6: WO-1004 | B6: EQ-100 | C6: Diesel Generator A-100 | D6: Preventive | E6: High | F6: Completed | G6: 2025-01-07 | H6: 2025-01-07 21:44 | I6: 2025-01-07 21:44 | J6: 2025-01-08 08:20 | K6: 8.7 | L6: 103559.2 | M6: No Failure | N6: Chidi Eze | O6: Preventive maintenance on Diesel Generator A-100 | P6: =TEXT(G6,"yyyy-mm") -> 2025-01 | Q6: =IF(tblWO[[#This Row],[Status]]="Completed",1, IF(tblWO[[#This Row],[Status]]="In Progress",2, IF(tblWO[[#This Row],[Status]]="Planned",3, IF(tblWO[[#This Row],[Status]]="Cancelled",4,99)))) -> 1 | R6: =IF(D6="Preventive",1, IF(D6="Inspection",2, IF(D6="Corrective",3, IF(D6="Breakdown",4, IF(D6="Overhaul",5,99))))) -> 1 | S6: =TEXT(G6,"yyyy-mm") -> 2025-01
A7: WO-1005 | B7: EQ-100 | C7: Diesel Generator A-100 | D7: Breakdown | E7: Low | F7: Completed | G7: 2025-10-13 | H7: 2025-10-13 21:44 | I7: 2025-10-13 21:44 | J7: 2025-10-15 00:39 | K7: 15.6 | L7: 258158.49 | M7: Calibration Drift | N7: Tunde Adeleke | O7: Breakdown maintenance on Diesel Generator A-100 | P7: =TEXT(G7,"yyyy-mm") -> 2025-10 | Q7: =IF(tblWO[[#This Row],[Status]]="Completed",1, IF(tblWO[[#This Row],[Status]]="In Progress",2, IF(tblWO[[#This Row],[Status]]="Planned",3, IF(tblWO[[#This Row],[Status]]="Cancelled",4,99)))) -> 1 | R7: =IF(D7="Preventive",1, IF(D7="Inspection",2, IF(D7="Corrective",3, IF(D7="Breakdown",4, IF(D7="Overhaul",5,99))))) -> 4 | S7: =TEXT(G7,"yyyy-mm") -> 2025-10
A8: WO-1006 | B8: EQ-100 | C8: Diesel Generator A-100 | D8: Preventive | E8: Medium | F8: Completed | G8: 2025-07-20 | H8: 2025-07-20 21:44 | I8: 2025-07-20 21:44 | J8: 2025-07-21 04:24 | K8: 11.8 | L8: 74604.47 | M8: No Failure | N8: Tunde Adeleke | O8: Preventive maintenance on Diesel Generator A-100 | P8: =TEXT(G8,"yyyy-mm") -> 2025-07 | Q8: =IF(tblWO[[#This Row],[Status]]="Completed",1, IF(tblWO[[#This Row],[Status]]="In Progress",2, IF(tblWO[[#This Row],[Status]]="Planned",3, IF(tblWO[[#This Row],[Status]]="Cancelled",4,99)))) -> 1 | R8: =IF(D8="Preventive",1, IF(D8="Inspection",2, IF(D8="Corrective",3, IF(D8="Breakdown",4, IF(D8="Overhaul",5,99))))) -> 1 | S8: =TEXT(G8,"yyyy-mm") -> 2025-07
A9: WO-1007 | B9: EQ-100 | C9: Diesel Generator A-100 | D9: Breakdown | E9: Critical | F9: Completed | G9: 2025-04-28 | H9: 2025-04-28 21:44 | I9: 2025-04-28 21:44 | J9: 2025-04-29 13:24 | K9: 15.3 | L9: 477576.84 | M9: Bearing Wear | N9: Amina Ibrahim | O9: Breakdown maintenance on Diesel Generator A-100 | P9: =TEXT(G9,"yyyy-mm") -> 2025-04 | Q9: =IF(tblWO[[#This Row],[Status]]="Completed",1, IF(tblWO[[#This Row],[Status]]="In Progress",2, IF(tblWO[[#This Row],[Status]]="Planned",3, IF(tblWO[[#This Row],[Status]]="Cancelled",4,99)))) -> 1 | R9: =IF(D9="Preventive",1, IF(D9="Inspection",2, IF(D9="Corrective",3, IF(D9="Breakdown",4, IF(D9="Overhaul",5,99))))) -> 4 | S9: =TEXT(G9,"yyyy-mm") -> 2025-04
A10: WO-1008 | B10: EQ-100 | C10: Diesel Generator A-100 | D10: Preventive | E10: Medium | F10: Completed | G10: 2025-09-29 | H10: 2025-09-29 21:44 | I10: 2025-09-29 21:44 | J10: 2025-09-30 00:43 | K10: 2.1 | L10: 73315.69 | M10: No Failure | N10: Fatima Bello | O10: Preventive maintenance on Diesel Generator A-100 | P10: =TEXT(G10,"yyyy-mm") -> 2025-09 | Q10: =IF(tblWO[[#This Row],[Status]]="Completed",1, IF(tblWO[[#This Row],[Status]]="In Progress",2, IF(tblWO[[#This Row],[Status]]="Planned",3, IF(tblWO[[#This Row],[Status]]="Cancelled",4,99)))) -> 1 | R10: =IF(D10="Preventive",1, IF(D10="Inspection",2, IF(D10="Corrective",3, IF(D10="Breakdown",4, IF(D10="Overhaul",5,99))))) -> 1 | S10: =TEXT(G10,"yyyy-mm") -> 2025-09
A11: WO-1009 | B11: EQ-100 | C11: Diesel Generator A-100 | D11: Preventive | E11: Low | F11: In Progress | G11: 2025-08-27 | H11: 2025-08-27 21:44 | K11: 0 | L11: 0 | N11: Chidi Eze | O11: Preventive maintenance on Diesel Generator A-100 | P11: =TEXT(G11,"yyyy-mm") -> 2025-08 | Q11: =IF(tblWO[[#This Row],[Status]]="Completed",1, IF(tblWO[[#This Row],[Status]]="In Progress",2, IF(tblWO[[#This Row],[Status]]="Planned",3, IF(tblWO[[#This Row],[Status]]="Cancelled",4,99)))) -> 2 | R11: =IF(D11="Preventive",1, IF(D11="Inspection",2, IF(D11="Corrective",3, IF(D11="Breakdown",4, IF(D11="Overhaul",5,99))))) -> 1 | S11: =TEXT(G11,"yyyy-mm") -> 2025-08
A12: WO-1010 | B12: EQ-100 | C12: Diesel Generator A-100 | D12: Preventive | E12: Medium | F12: Completed | G12: 2025-07-09 | H12: 2025-07-09 21:44 | I12: 2025-07-09 21:44 | J12: 2025-07-10 02:23 | K12: 6.2 | L12: 289329.41 | M12: No Failure | N12: Zainab Yusuf | O12: Preventive maintenance on Diesel Generator A-100 | P12: =TEXT(G12,"yyyy-mm") -> 2025-07 | Q12: =IF(tblWO[[#This Row],[Status]]="Completed",1, IF(tblWO[[#This Row],[Status]]="In Progress",2, IF(tblWO[[#This Row],[Status]]="Planned",3, IF(tblWO[[#This Row],[Status]]="Cancelled",4,99)))) -> 1 | R12: =IF(D12="Preventive",1, IF(D12="Inspection",2, IF(D12="Corrective",3, IF(D12="Breakdown",4, IF(D12="Overhaul",5,99))))) -> 1 | S12: =TEXT(G12,"yyyy-mm") -> 2025-07
A13: WO-1011 | B13: EQ-100 | C13: Diesel Generator A-100 | D13: Preventive | E13: Medium | F13: Completed | G13: 2025-05-22 | H13: 2025-05-22 21:44 | I13: 2025-05-22 21:44 | J13: 2025-05-23 01:55 | K13: 2.6 | L13: 128401.2 | M13: No Failure | N13: John Okafor | O13: Preventive maintenance on Diesel Generator A-100 | P13: =TEXT(G13,"yyyy-mm") -> 2025-05 | Q13: =IF(tblWO[[#This Row],[Status]]="Completed",1, IF(tblWO[[#This Row],[Status]]="In Progress",2, IF(tblWO[[#This Row],[Status]]="Planned",3, IF(tblWO[[#This Row],[Status]]="Cancelled",4,99)))) -> 1 | R13: =IF(D13="Preventive",1, IF(D13="Inspection",2, IF(D13="Corrective",3, IF(D13="Breakdown",4, IF(D13="Overhaul",5,99))))) -> 1 | S13: =TEXT(G13,"yyyy-mm") -> 2025-05
A14: WO-1012 | B14: EQ-100 | C14: Diesel Generator A-100 | D14: Corrective | E14: Critical | F14: Planned | G14: 2025-09-19 | H14: 2025-09-19 21:44 | K14: 0 | L14: 0 | N14: Chidi Eze | O14: Corrective maintenance on Diesel Generator A-100 | P14: =TEXT(G14,"yyyy-mm") -> 2025-09 | Q14: =IF(tblWO[[#This Row],[Status]]="Completed",1, IF(tblWO[[#This Row],[Status]]="In Progress",2, IF(tblWO[[#This Row],[Status]]="Planned",3, IF(tblWO[[#This Row],[Status]]="Cancelled",4,99)))) -> 3 | R14: =IF(D14="Preventive",1, IF(D14="Inspection",2, IF(D14="Corrective",3, IF(D14="Breakdown",4, IF(D14="Overhaul",5,99))))) -> 3 | S14: =TEXT(G14,"yyyy-mm") -> 2025-09
A15: WO-1013 | B15: EQ-100 | C15: Diesel Generator A-100 | D15: Preventive | E15: Critical | F15: Completed | G15: 2025-01-25 | H15: 2025-01-25 21:44 | I15: 2025-01-25 21:44 | J15: 2025-01-26 06:29 | K15: 10.9 | L15: 111553.84 | M15: No Failure | N15: John Okafor | O15: Preventive maintenance on Diesel Generator A-100 | P15: =TEXT(G15,"yyyy-mm") -> 2025-01 | Q15: =IF(tblWO[[#This Row],[Status]]="Completed",1, IF(tblWO[[#This Row],[Status]]="In Progress",2, IF(tblWO[[#This Row],[Status]]="Planned",3, IF(tblWO[[#This Row],[Status]]="Cancelled",4,99)))) -> 1 | R15: =IF(D15="Preventive",1, IF(D15="Inspection",2, IF(D15="Corrective",3, IF(D15="Breakdown",4, IF(D15="Overhaul",5,99))))) -> 1 | S15: =TEXT(G15,"yyyy-mm") -> 2025-01
A16: WO-1014 | B16: EQ-100 | C16: Diesel Generator A-100 | D16: Corrective | E16: Low | F16: Completed | G16: 2025-11-23 | H16: 2025-11-23 21:44 | I16: 2025-11-23 21:44 | J16: 2025-11-24 13:25 | K16: 8.1 | L16: 386476.72 | M16: Electrical Fault | N16: Fatima Bello | O16: Corrective maintenance on Diesel Generator A-100 | P16: =TEXT(G16,"yyyy-mm") -> 2025-11 | Q16: =IF(tblWO[[#This Row],[Status]]="Completed",1, IF(tblWO[[#This Row],[Status]]="In Progress",2, IF(tblWO[[#This Row],[Status]]="Planned",3, IF(tblWO[[#This Row],[Status]]="Cancelled",4,99)))) -> 1 | R16: =IF(D16="Preventive",1, IF(D16="Inspection",2, IF(D16="Corrective",3, IF(D16="Breakdown",4, IF(D16="Overhaul",5,99))))) -> 3 | S16: =TEXT(G16,"yyyy-mm") -> 2025-11
A17: WO-1015 | B17: EQ-100 | C17: Diesel Generator A-100 | D17: Preventive | E17: High | F17: Completed | G17: 2025-02-27 | H17: 2025-02-27 21:44 | I17: 2025-02-27 21:44 | J17: 2025-02-28 06:27 | K17: 9.5 | L17: 68135.78 | M17: No Failure | N17: Zainab Yusuf | O17: Preventive maintenance on Diesel Generator A-100 | P17: =TEXT(G17,"yyyy-mm") -> 2025-02 | Q17: =IF(tblWO[[#This Row],[Status]]="Completed",1, IF(tblWO[[#This Row],[Status]]="In Progress",2, IF(tblWO[[#This Row],[Status]]="Planned",3, IF(tblWO[[#This Row],[Status]]="Cancelled",4,99)))) -> 1 | R17: =IF(D17="Preventive",1, IF(D17="Inspection",2, IF(D17="Corrective",3, IF(D17="Breakdown",4, IF(D17="Overhaul",5,99))))) -> 1 | S17: =TEXT(G17,"yyyy-mm") -> 2025-02
A18: WO-1016 | B18: EQ-100 | C18: Diesel Generator A-100 | D18: Corrective | E18: High | F18: Completed | G18: 2025-02-11 | H18: 2025-02-11 21:44 | I18: 2025-02-11 21:44 | J18: 2025-02-12 03:12 | K18: 22.7 | L18: 452345.67 | M18: Calibration Drift | N18: Fatima Bello | O18: Corrective maintenance on Diesel Generator A-100 | P18: =TEXT(G18,"yyyy-mm") -> 2025-02 | Q18: =IF(tblWO[[#This Row],[Status]]="Completed",1, IF(tblWO[[#This Row],[Status]]="In Progress",2, IF(tblWO[[#This Row],[Status]]="Planned",3, IF(tblWO[[#This Row],[Status]]="Cancelled",4,99)))) -> 1 | R18: =IF(D18="Preventive",1, IF(D18="Inspection",2, IF(D18="Corrective",3, IF(D18="Breakdown",4, IF(D18="Overhaul",5,99))))) -> 3 | S18: =TEXT(G18,"yyyy-mm") -> 2025-02
A19: WO-1017 | B19: EQ-100 | C19: Diesel Generator A-100 | D19: Preventive | E19: High | F19: Completed | G19: 2025-03-12 | H19: 2025-03-12 21:44 | I19: 2025-03-12 21:44 | J19: 2025-03-13 04:07 | K19: 11.8 | L19: 251774.99 | M19: No Failure | N19: John Okafor | O19: Preventive maintenance on Diesel Generator A-100 | P19: =TEXT(G19,"yyyy-mm") -> 2025-03 | Q19: =IF(tblWO[[#This Row],[Status]]="Completed",1, IF(tblWO[[#This Row],[Status]]="In Progress",2, IF(tblWO[[#This Row],[Status]]="Planned",3, IF(tblWO[[#This Row],[Status]]="Cancelled",4,99)))) -> 1 | R19: =IF(D19="Preventive",1, IF(D19="Inspection",2, IF(D19="Corrective",3, IF(D19="Breakdown",4, IF(D19="Overhaul",5,99))))) -> 1 | S19: =TEXT(G19,"yyyy-mm") -> 2025-03
A20: WO-1018 | B20: EQ-101 | C20: Gas Turbine A-101 | D20: Breakdown | E20: High | F20: In Progress | G20: 2025-11-26 | H20: 2025-11-26 21:44 | K20: 0 | L20: 0 | N20: Amina Ibrahim | O20: Breakdown maintenance on Gas Turbine A-101 | P20: =TEXT(G20,"yyyy-mm") -> 2025-11 | Q20: =IF(tblWO[[#This Row],[Status]]="Completed",1, IF(tblWO[[#This Row],[Status]]="In Progress",2, IF(tblWO[[#This Row],[Status]]="Planned",3, IF(tblWO[[#This Row],[Status]]="Cancelled",4,99)))) -> 2 | R20: =IF(D20="Preventive",1, IF(D20="Inspection",2, IF(D20="Corrective",3, IF(D20="Breakdown",4, IF(D20="Overhaul",5,99))))) -> 4 | S20: =TEXT(G20,"yyyy-mm") -> 2025-11
A21: WO-1019 | B21: EQ-101 | C21: Gas Turbine A-101 | D21: Breakdown | E21: High | F21: Completed | G21: 2025-05-10 | H21: 2025-05-10 21:44 | I21: 2025-05-10 21:44 | J21: 2025-05-11 17:00 | K21: 35.5 | L21: 711747.69 | M21: Corrosion | N21: Zainab Yusuf | O21: Breakdown maintenance on Gas Turbine A-101 | P21: =TEXT(G21,"yyyy-mm") -> 2025-05 | Q21: =IF(tblWO[[#This Row],[Status]]="Completed",1, IF(tblWO[[#This Row],[Status]]="In Progress",2, IF(tblWO[[#This Row],[Status]]="Planned",3, IF(tblWO[[#This Row],[Status]]="Cancelled",4,99)))) -> 1 | R21: =IF(D21="Preventive",1, IF(D21="Inspection",2, IF(D21="Corrective",3, IF(D21="Breakdown",4, IF(D21="Overhaul",5,99))))) -> 4 | S21: =TEXT(G21,"yyyy-mm") -> 2025-05
A22: WO-1020 | B22: EQ-101 | C22: Gas Turbine A-101 | D22: Preventive | E22: High | F22: Completed | G22: 2025-01-17 | H22: 2025-01-17 21:44 | I22: 2025-01-17 21:44 | J22: 2025-01-18 00:40 | K22: 2 | L22: 242779.81 | M22: No Failure | N22: Emeka Okonkwo | O22: Preventive maintenance on Gas Turbine A-101 | P22: =TEXT(G22,"yyyy-mm") -> 2025-01 | Q22: =IF(tblWO[[#This Row],[Status]]="Completed",1, IF(tblWO[[#This Row],[Status]]="In Progress",2, IF(tblWO[[#This Row],[Status]]="Planned",3, IF(tblWO[[#This Row],[Status]]="Cancelled",4,99)))) -> 1 | R22: =IF(D22="Preventive",1, IF(D22="Inspection",2, IF(D22="Corrective",3, IF(D22="Breakdown",4, IF(D22="Overhaul",5,99))))) -> 1 | S22: =TEXT(G22,"yyyy-mm") -> 2025-01
A23: WO-1021 | B23: EQ-101 | C23: Gas Turbine A-101 | D23: Preventive | E23: Critical | F23: Completed | G23: 2025-08-05 | H23: 2025-08-05 21:44 | I23: 2025-08-05 21:44 | J23: 2025-08-06 05:15 | K23: 2.8 | L23: 270776.6 | M23: No Failure | N23: Chidi Eze | O23: Preventive maintenance on Gas Turbine A-101 | P23: =TEXT(G23,"yyyy-mm") -> 2025-08 | Q23: =IF(tblWO[[#This Row],[Status]]="Completed",1, IF(tblWO[[#This Row],[Status]]="In Progress",2, IF(tblWO[[#This Row],[Status]]="Planned",3, IF(tblWO[[#This Row],[Status]]="Cancelled",4,99)))) -> 1 | R23: =IF(D23="Preventive",1, IF(D23="Inspection",2, IF(D23="Corrective",3, IF(D23="Breakdown",4, IF(D23="Overhaul",5,99))))) -> 1 | S23: =TEXT(G23,"yyyy-mm") -> 2025-08
A24: WO-1022 | B24: EQ-101 | C24: Gas Turbine A-101 | D24: Corrective | E24: Critical | F24: Completed | G24: 2025-10-16 | H24: 2025-10-16 21:44 | I24: 2025-10-16 21:44 | J24: 2025-10-17 12:47 | K24: 11.3 | L24: 473235.2 | M24: Leakage | N24: John Okafor | O24: Corrective maintenance on Gas Turbine A-101 | P24: =TEXT(G24,"yyyy-mm") -> 2025-10 | Q24: =IF(tblWO[[#This Row],[Status]]="Completed",1, IF(tblWO[[#This Row],[Status]]="In Progress",2, IF(tblWO[[#This Row],[Status]]="Planned",3, IF(tblWO[[#This Row],[Status]]="Cancelled",4,99)))) -> 1 | R24: =IF(D24="Preventive",1, IF(D24="Inspection",2, IF(D24="Corrective",3, IF(D24="Breakdown",4, IF(D24="Overhaul",5,99))))) -> 3 | S24: =TEXT(G24,"yyyy-mm") -> 2025-10
A25: WO-1023 | B25: EQ-101 | C25: Gas Turbine A-101 | D25: Inspection | E25: High | F25: Completed | G25: 2025-04-08 | H25: 2025-04-08 21:44 | I25: 2025-04-08 21:44 | J25: 2025-04-09 00:47 | K25: 2.7 | L25: 89977.02 | M25: No Failure | N25: Chidi Eze | O25: Inspection maintenance on Gas Turbine A-101 | P25: =TEXT(G25,"yyyy-mm") -> 2025-04 | Q25: =IF(tblWO[[#This Row],[Status]]="Completed",1, IF(tblWO[[#This Row],[Status]]="In Progress",2, IF(tblWO[[#This Row],[Status]]="Planned",3, IF(tblWO[[#This Row],[Status]]="Cancelled",4,99)))) -> 1 | R25: =IF(D25="Preventive",1, IF(D25="Inspection",2, IF(D25="Corrective",3, IF(D25="Breakdown",4, IF(D25="Overhaul",5,99))))) -> 2 | S25: =TEXT(G25,"yyyy-mm") -> 2025-04
A26: WO-1024 | B26: EQ-101 | C26: Gas Turbine A-101 | D26: Inspection | E26: Low | F26: Planned | G26: 2025-04-22 | H26: 2025-04-22 21:44 | K26: 0 | L26: 0 | N26: Tunde Adeleke | O26: Inspection maintenance on Gas Turbine A-101 | P26: =TEXT(G26,"yyyy-mm") -> 2025-04 | Q26: =IF(tblWO[[#This Row],[Status]]="Completed",1, IF(tblWO[[#This Row],[Status]]="In Progress",2, IF(tblWO[[#This Row],[Status]]="Planned",3, IF(tblWO[[#This Row],[Status]]="Cancelled",4,99)))) -> 3 | R26: =IF(D26="Preventive",1, IF(D26="Inspection",2, IF(D26="Corrective",3, IF(D26="Breakdown",4, IF(D26="Overhaul",5,99))))) -> 2 | S26: =TEXT(G26,"yyyy-mm") -> 2025-04
A27: WO-1025 | B27: EQ-101 | C27: Gas Turbine A-101 | D27: Preventive | E27: Medium | F27: Completed | G27: 2025-06-10 | H27: 2025-06-10 21:44 | I27: 2025-06-10 21:44 | J27: 2025-06-11 07:34 | K27: 9.4 | L27: 112041.81 | M27: No Failure | N27: Chidi Eze | O27: Preventive maintenance on Gas Turbine A-101 | P27: =TEXT(G27,"yyyy-mm") -> 2025-06 | Q27: =IF(tblWO[[#This Row],[Status]]="Completed",1, IF(tblWO[[#This Row],[Status]]="In Progress",2, IF(tblWO[[#This Row],[Status]]="Planned",3, IF(tblWO[[#This Row],[Status]]="Cancelled",4,99)))) -> 1 | R27: =IF(D27="Preventive",1, IF(D27="Inspection",2, IF(D27="Corrective",3, IF(D27="Breakdown",4, IF(D27="Overhaul",5,99))))) -> 1 | S27: =TEXT(G27,"yyyy-mm") -> 2025-06
A28: WO-1026 | B28: EQ-101 | C28: Gas Turbine A-101 | D28: Breakdown | E28: High | F28: In Progress | G28: 2025-07-05 | H28: 2025-07-05 21:44 | K28: 0 | L28: 0 | N28: Zainab Yusuf | O28: Breakdown maintenance on Gas Turbine A-101 | P28: =TEXT(G28,"yyyy-mm") -> 2025-07 | Q28: =IF(tblWO[[#This Row],[Status]]="Completed",1, IF(tblWO[[#This Row],[Status]]="In Progress",2, IF(tblWO[[#This Row],[Status]]="Planned",3, IF(tblWO[[#This Row],[Status]]="Cancelled",4,99)))) -> 2 | R28: =IF(D28="Preventive",1, IF(D28="Inspection",2, IF(D28="Corrective",3, IF(D28="Breakdown",4, IF(D28="Overhaul",5,99))))) -> 4 | S28: =TEXT(G28,"yyyy-mm") -> 2025-07
A29: WO-1027 | B29: EQ-101 | C29: Gas Turbine A-101 | D29: Preventive | E29: High | F29: Completed | G29: 2025-04-17 | H29: 2025-04-17 21:44 | I29: 2025-04-17 21:44 | J29: 2025-04-18 01:58 | K29: 4.8 | L29: 67355.19 | M29: No Failure | N29: Emeka Okonkwo | O29: Preventive maintenance on Gas Turbine A-101 | P29: =TEXT(G29,"yyyy-mm") -> 2025-04 | Q29: =IF(tblWO[[#This Row],[Status]]="Completed",1, IF(tblWO[[#This Row],[Status]]="In Progress",2, IF(tblWO[[#This Row],[Status]]="Planned",3, IF(tblWO[[#This Row],[Status]]="Cancelled",4,99)))) -> 1 | R29: =IF(D29="Preventive",1, IF(D29="Inspection",2, IF(D29="Corrective",3, IF(D29="Breakdown",4, IF(D29="Overhaul",5,99))))) -> 1 | S29: =TEXT(G29,"yyyy-mm") -> 2025-04
A30: WO-1028 | B30: EQ-101 | C30: Gas Turbine A-101 | D30: Preventive | E30: Medium | F30: Cancelled | G30: 2025-09-08 | H30: 2025-09-08 21:44 | K30: 0 | L30: 0 | N30: John Okafor | O30: Preventive maintenance on Gas Turbine A-101 | P30: =TEXT(G30,"yyyy-mm") -> 2025-09 | Q30: =IF(tblWO[[#This Row],[Status]]="Completed",1, IF(tblWO[[#This Row],[Status]]="In Progress",2, IF(tblWO[[#This Row],[Status]]="Planned",3, IF(tblWO[[#This Row],[Status]]="Cancelled",4,99)))) -> 4 | R30: =IF(D30="Preventive",1, IF(D30="Inspection",2, IF(D30="Corrective",3, IF(D30="Breakdown",4, IF(D30="Overhaul",5,99))))) -> 1 | S30: =TEXT(G30,"yyyy-mm") -> 2025-09
A31: WO-1029 | B31: EQ-101 | C31: Gas Turbine A-101 | D31: Preventive | E31: High | F31: Planned | G31: 2025-05-04 | H31: 2025-05-04 21:44 | K31: 0 | L31: 0 | N31: Amina Ibrahim | O31: Preventive maintenance on Gas Turbine A-101 | P31: =TEXT(G31,"yyyy-mm") -> 2025-05 | Q31: =IF(tblWO[[#This Row],[Status]]="Completed",1, IF(tblWO[[#This Row],[Status]]="In Progress",2, IF(tblWO[[#This Row],[Status]]="Planned",3, IF(tblWO[[#This Row],[Status]]="Cancelled",4,99)))) -> 3 | R31: =IF(D31="Preventive",1, IF(D31="Inspection",2, IF(D31="Corrective",3, IF(D31="Breakdown",4, IF(D31="Overhaul",5,99))))) -> 1 | S31: =TEXT(G31,"yyyy-mm") -> 2025-05
A32: WO-1030 | B32: EQ-101 | C32: Gas Turbine A-101 | D32: Corrective | E32: Critical | F32: Cancelled | G32: 2025-05-31 | H32: 2025-05-31 21:44 | K32: 0 | L32: 0 | N32: Fatima Bello | O32: Corrective maintenance on Gas Turbine A-101 | P32: =TEXT(G32,"yyyy-mm") -> 2025-05 | Q32: =IF(tblWO[[#This Row],[Status]]="Completed",1, IF(tblWO[[#This Row],[Status]]="In Progress",2, IF(tblWO[[#This Row],[Status]]="Planned",3, IF(tblWO[[#This Row],[Status]]="Cancelled",4,99)))) -> 4 | R32: =IF(D32="Preventive",1, IF(D32="Inspection",2, IF(D32="Corrective",3, IF(D32="Breakdown",4, IF(D32="Overhaul",5,99))))) -> 3 | S32: =TEXT(G32,"yyyy-mm") -> 2025-05
A33: WO-1031 | B33: EQ-101 | C33: Gas Turbine A-101 | D33: Preventive | E33: Low | F33: Completed | G33: 2025-12-19 | H33: 2025-12-19 21:44 | I33: 2025-12-19 21:44 | J33: 2025-12-20 04:06 | K33: 8.9 | L33: 285065.78 | M33: No Failure | N33: Fatima Bello | O33: Preventive maintenance on Gas Turbine A-101 | P33: =TEXT(G33,"yyyy-mm") -> 2025-12 | Q33: =IF(tblWO[[#This Row],[Status]]="Completed",1, IF(tblWO[[#This Row],[Status]]="In Progress",2, IF(tblWO[[#This Row],[Status]]="Planned",3, IF(tblWO[[#This Row],[Status]]="Cancelled",4,99)))) -> 1 | R33: =IF(D33="Preventive",1, IF(D33="Inspection",2, IF(D33="Corrective",3, IF(D33="Breakdown",4, IF(D33="Overhaul",5,99))))) -> 1 | S33: =TEXT(G33,"yyyy-mm") -> 2025-12
A34: WO-1032 | B34: EQ-101 | C34: Gas Turbine A-101 | D34: Preventive | E34: Medium | F34: In Progress | G34: 2025-01-26 | H34: 2025-01-26 21:44 | K34: 0 | L34: 0 | N34: Amina Ibrahim | O34: Preventive maintenance on Gas Turbine A-101 | P34: =TEXT(G34,"yyyy-mm") -> 2025-01 | Q34: =IF(tblWO[[#This Row],[Status]]="Completed",1, IF(tblWO[[#This Row],[Status]]="In Progress",2, IF(tblWO[[#This Row],[Status]]="Planned",3, IF(tblWO[[#This Row],[Status]]="Cancelled",4,99)))) -> 2 | R34: =IF(D34="Preventive",1, IF(D34="Inspection",2, IF(D34="Corrective",3, IF(D34="Breakdown",4, IF(D34="Overhaul",5,99))))) -> 1 | S34: =TEXT(G34,"yyyy-mm") -> 2025-01
A35: WO-1033 | B35: EQ-101 | C35: Gas Turbine A-101 | D35: Breakdown | E35: Medium | F35: Completed | G35: 2025-09-07 | H35: 2025-09-07 21:44 | I35: 2025-09-07 21:44 | J35: 2025-09-08 18:07 | K35: 19.8 | L35: 276372.68 | M35: Overheating | N35: Tunde Adeleke | O35: Breakdown maintenance on Gas Turbine A-101 | P35: =TEXT(G35,"yyyy-mm") -> 2025-09 | Q35: =IF(tblWO[[#This Row],[Status]]="Completed",1, IF(tblWO[[#This Row],[Status]]="In Progress",2, IF(tblWO[[#This Row],[Status]]="Planned",3, IF(tblWO[[#This Row],[Status]]="Cancelled",4,99)))) -> 1 | R35: =IF(D35="Preventive",1, IF(D35="Inspection",2, IF(D35="Corrective",3, IF(D35="Breakdown",4, IF(D35="Overhaul",5,99))))) -> 4 | S35: =TEXT(G35,"yyyy-mm") -> 2025-09
A36: WO-1034 | B36: EQ-101 | C36: Gas Turbine A-101 | D36: Corrective | E36: Medium | F36: Completed | G36: 2025-12-03 | H36: 2025-12-03 21:44 | I36: 2025-12-03 21:44 | J36: 2025-12-04 16:42 | K36: 12.1 | L36: 433490.07 | M36: Electrical Fault | N36: Emeka Okonkwo | O36: Corrective maintenance on Gas Turbine A-101 | P36: =TEXT(G36,"yyyy-mm") -> 2025-12 | Q36: =IF(tblWO[[#This Row],[Status]]="Completed",1, IF(tblWO[[#This Row],[Status]]="In Progress",2, IF(tblWO[[#This Row],[Status]]="Planned",3, IF(tblWO[[#This Row],[Status]]="Cancelled",4,99)))) -> 1 | R36: =IF(D36="Preventive",1, IF(D36="Inspection",2, IF(D36="Corrective",3, IF(D36="Breakdown",4, IF(D36="Overhaul",5,99))))) -> 3 | S36: =TEXT(G36,"yyyy-mm") -> 2025-12
A37: WO-1035 | B37: EQ-101 | C37: Gas Turbine A-101 | D37: Preventive | E37: High | F37: Completed | G37: 2025-07-30 | H37: 2025-07-30 21:44 | I37: 2025-07-30 21:44 | J37: 2025-07-31 07:36 | K37: 6.4 | L37: 218906.81 | M37: No Failure | N37: Zainab Yusuf | O37: Preventive maintenance on Gas Turbine A-101 | P37: =TEXT(G37,"yyyy-mm") -> 2025-07 | Q37: =IF(tblWO[[#This Row],[Status]]="Completed",1, IF(tblWO[[#This Row],[Status]]="In Progress",2, IF(tblWO[[#This Row],[Status]]="Planned",3, IF(tblWO[[#This Row],[Status]]="Cancelled",4,99)))) -> 1 | R37: =IF(D37="Preventive",1, IF(D37="Inspection",2, IF(D37="Corrective",3, IF(D37="Breakdown",4, IF(D37="Overhaul",5,99))))) -> 1 | S37: =TEXT(G37,"yyyy-mm") -> 2025-07
A38: WO-1036 | B38: EQ-101 | C38: Gas Turbine A-101 | D38: Breakdown | E38: Medium | F38: Completed | G38: 2025-11-24 | H38: 2025-11-24 21:44 | I38: 2025-11-24 21:44 | J38: 2025-11-25 09:08 | K38: 21.4 | L38: 691054.08 | M38: Corrosion | N38: Fatima Bello | O38: Breakdown maintenance on Gas Turbine A-101 | P38: =TEXT(G38,"yyyy-mm") -> 2025-11 | Q38: =IF(tblWO[[#This Row],[Status]]="Completed",1, IF(tblWO[[#This Row],[Status]]="In Progress",2, IF(tblWO[[#This Row],[Status]]="Planned",3, IF(tblWO[[#This Row],[Status]]="Cancelled",4,99)))) -> 1 | R38: =IF(D38="Preventive",1, IF(D38="Inspection",2, IF(D38="Corrective",3, IF(D38="Breakdown",4, IF(D38="Overhaul",5,99))))) -> 4 | S38: =TEXT(G38,"yyyy-mm") -> 2025-11
A39: WO-1037 | B39: EQ-101 | C39: Gas Turbine A-101 | D39: Corrective | E39: Low | F39: Completed | G39: 2025-04-02 | H39: 2025-04-02 21:44 | I39: 2025-04-02 21:44 | J39: 2025-04-03 04:41 | K39: 16.2 | L39: 407395.74 | M39: Vibration | N39: Zainab Yusuf | O39: Corrective maintenance on Gas Turbine A-101 | P39: =TEXT(G39,"yyyy-mm") -> 2025-04 | Q39: =IF(tblWO[[#This Row],[Status]]="Completed",1, IF(tblWO[[#This Row],[Status]]="In Progress",2, IF(tblWO[[#This Row],[Status]]="Planned",3, IF(tblWO[[#This Row],[Status]]="Cancelled",4,99)))) -> 1 | R39: =IF(D39="Preventive",1, IF(D39="Inspection",2, IF(D39="Corrective",3, IF(D39="Breakdown",4, IF(D39="Overhaul",5,99))))) -> 3 | S39: =TEXT(G39,"yyyy-mm") -> 2025-04
A40: WO-1038 | B40: EQ-101 | C40: Gas Turbine A-101 | D40: Preventive | E40: High | F40: Completed | G40: 2025-11-09 | H40: 2025-11-09 21:44 | I40: 2025-11-09 21:44 | J40: 2025-11-10 05:30 | K40: 6 | L40: 86892.84 | M40: No Failure | N40: John Okafor | O40: Preventive maintenance on Gas Turbine A-101 | P40: =TEXT(G40,"yyyy-mm") -> 2025-11 | Q40: =IF(tblWO[[#This Row],[Status]]="Completed",1, IF(tblWO[[#This Row],[Status]]="In Progress",2, IF(tblWO[[#This Row],[Status]]="Planned",3, IF(tblWO[[#This Row],[Status]]="Cancelled",4,99)))) -> 1 | R40: =IF(D40="Preventive",1, IF(D40="Inspection",2, IF(D40="Corrective",3, IF(D40="Breakdown",4, IF(D40="Overhaul",5,99))))) -> 1 | S40: =TEXT(G40,"yyyy-mm") -> 2025-11
...

Sheet Equipment_Metrics
A1: Equipment_ID | B1: Total_Work_Orders | C1: Total_Downtime_Hours | D1: Total_Cost_NGN | E1: MTBF_Hours | F1: MTTR_Hours | G1: Availability_Pct
A2: EQ-100 | B2: 15 | C2: 139.4 | D2: 2863344.8 | E2: 4380 | F2: 9.3 | G2: 98.41
A3: EQ-101 | B3: 17 | C3: 205 | D3: 5004671.4 | E3: 2190 | F3: 12.1 | G3: 97.66
A4: EQ-102 | B4: 13 | C4: 171 | D4: 2921472 | E4: 2920 | F4: 13.2 | G4: 98.05
A5: EQ-103 | B5: 22 | C5: 304.9 | D5: 5086337 | E5: 2920 | F5: 13.9 | G5: 96.52
A6: EQ-104 | B6: 6 | C6: 92.1 | D6: 1898449.3 | E6: 2920 | F6: 15.4 | G6: 98.95
A7: EQ-105 | B7: 15 | C7: 212.1 | D7: 4352095.7 | E7: 2920 | F7: 14.1 | G7: 97.58
A8: EQ-106 | B8: 22 | C8: 183.6 | D8: 5071478.6 | E8: 2920 | F8: 8.3 | G8: 97.9
A9: EQ-107 | B9: 8 | C9: 83.7 | D9: 2250966.3 | E9: 4380 | F9: 10.5 | G9: 99.04
A10: EQ-108 | B10: 4 | C10: 95.9 | D10: 1872736.9 | E10: 8760 | F10: 24 | G10: 98.91
A11: EQ-109 | B11: 12 | C11: 207.8 | D11: 3701480.7 | E11: 2190 | F11: 17.3 | G11: 97.63
A12: EQ-110 | B12: 13 | C12: 97.1 | D12: 2830912 | E12: 8760 | F12: 7.5 | G12: 98.89
A13: EQ-111 | B13: 6 | C13: 96 | D13: 2543839.2 | E13: 8760 | F13: 16 | G13: 98.9
... A31: EQ-129 | B31: 19 | C31: 159.9 | D31: 4382057.4 | E31: 4380 | F31: 8.4 | G31: 98.17

Sheet KPI_Summary
A1: Total_Equipment | B1: Total_Work_Orders | C1: Completed_WO | D1: In_Progress_WO | E1: Planned_WO | F1: Total_Downtime_Hours | G1: Total_Maintenance_Cost_NGN | H1: Avg_Downtime_Hours | I1: Avg_Cost_Per_WO_NGN | J1: Preventive_Maintenance_Pct | K1: Breakdown_Maintenance_Pct
A2: 30 | B2: 402 | C2: 330 | D2: 40 | E2: 23 | F2: 4221.2 | G2: 89101251 | H2: 12.791515 | I2: 270003.79 | J2: 50 | K2: 15.757576

Sheet Pivots
A1: Status_Order | B1: Status | C1: Work Orders
A2: 1 | B2: Completed | C2: 330
A3: 2 | B3: In Progress | C3: 40
A4: 3 | B4: Planned | C4: 23
A5: 4 | B5: Cancelled | C5: 9
A13: Status | B13: (All)
A15: Maintenance_Type_Order | B15: Maintenance_Type | C15: Count of WO_Number
A16: 1 | B16: Preventive | C16: 198
A17: 2 | B17: Inspection | C17: 35
A18: 3 | B18: Corrective | C18: 90
A19: 4 | B19: Breakdown | C19: 65
A20: 5 | B20: Overhaul | C20: 14
A28: Status | B28: (All)
A30: Year_Month | B30: Sum of Cost_NGN
A31: 2024-12 | B31: 1697933.1
A32: 2025-01 | B32: 4265011.9
A33: 2025-02 | B33: 7611409.9
A34: 2025-03 | B34: 6476371.7
A35: 2025-04 | B35: 7039637.3
A36: 2025-05 | B36: 5728906.3
A37: 2025-06 | B37: 7992180.4
A38: 2025-07 | B38: 9376258
A39: 2025-08 | B39: 8451315
A40: 2025-09 | B40: 7147153.3
A41: 2025-10 | B41: 8528918.9
A42: 2025-11 | B42: 7234946.8
A43: 2025-12 | B43: 7551208.4
A55: Equipment_ID | B55: Sum of Total_Downtime_Hours
A56: EQ-117 | B56: 180.2
A57: EQ-106 | B57: 183.6
A58: EQ-119 | B58: 195.8
A59: EQ-121 | B59: 204.1
A60: EQ-101 | B60: 205
A61: EQ-109 | B61: 207.8
A62: EQ-105 | B62: 212.1
A63: EQ-116 | B63: 219.3
A64: EQ-112 | B64: 221.1
A65: EQ-103 | B65: 304.9

Sheet Dashboard
B1: MAINTENANCE KPI DASHBOARD Oil & Gas Operations
B5: Total Work Orders | E5: Completed Work Orders | H5: Total Downtime (Hours) | K5: Total Maintenance Cost (₦) | M5: Avg Downtime per Work Order (hrs) | O5: Avg Cost per Work Order (₦) | Q5: Preventive Maintenance (%)
B6: =KPI_Summary!B2 -> 402 | E6: =_xlfn.XLOOKUP("Completed_WO",KPI_Summary!1:1,KPI_Summary!2:2) -> 330 | H6: =_xlfn.XLOOKUP("Total_Downtime_Hours",KPI_Summary!1:1,KPI_Summary!2:2) -> 4221.2 | K6: =_xlfn.XLOOKUP("Total_Maintenance_Cost_NGN",KPI_Summary!1:1,KPI_Summary!2:2) -> 89101251 | M6: =_xlfn.XLOOKUP("Avg_Downtime_Hours",KPI_Summary!1:1,KPI_Summary!2:2) -> 12.791515 | O6: =_xlfn.XLOOKUP("Avg_Cost_Per_WO_NGN",KPI_Summary!1:1,KPI_Summary!2:2) -> 270003.79 | Q6: =_xlfn.XLOOKUP("Preventive_Maintenance_Pct",KPI_Summary!1:1,KPI_Summary!2:2)/100 -> 0.5
T8: Use Status filter on Analysis tab
